Workbook

Sheet Purchase License Summary
A2: PURCHASED OS AND MS OFFICE LICENSES
A5: Windows OS Servers
A6: Office Name | B6: Puchased/Licensed Date | C6: Authorization Number | D6: License Number | E6: Distributor Purchase Order Number | F6: Microsoft Part Number | G6: Version | H6: Vendor | I6: Quantity
A7: Microsoft Windows Server CAL 2008 Single OPEN 1 Licensed No Level Device | B7: 40687 | C7: 68516159ZZS1305 | D7: 48539745 | E7: 004801 | F7: R18 - 02729 | G7: 2008 | H7: Dataworld Computer Center | I7: 40
A8: Microsoft Windows Server Standard 2008 R2 Single OPEN 1 Licensed No Level | B8: 40687 | C8: 68516159ZZS1305 | D8: 48539745 | E8: 004801 | F8: P73 - 04982 | G8: 2008 R | H8: Dataworld Computer Center | I8: 4
A9: Microsoft Windows Server STDCORE 2016 Single OLP 2 Licenses No Level CoreLic | B9: 42818 | C9: 98276546ZZS1903 | D9: 68213266 | E9: 100103668 | F9: 9EM-00124 | G9: 2016 | H9: Dataworld Computer Center | I9: 8
A10: TOTAL | I10: =SUM(I7:I9) -> 52
A12: OS LICENSES
A13: Office Name | B13: Puchased/Licensed Date | C13: Authorization Number | D13: License Number | E13: Distributor Purchase Order Number | F13: Microsoft Part Number | G13: Version | H13: Vendor | I13: Quantity
A14: Windows Professional 10 OLP NL Legalization GG | B14: 42818 | C14: 98279325ZZS1903 | D14: 68213269 | E14: 100103667 | F14: FQC - 09478 | G14: 2010 | H14: Dataworld Computer Center | I14: 24
A15: Microsoft Windows Professional 7 Single OPEN 1 License NO Level Legalization GG | B15: 40687 | C15: 68516923ZZS1305 | D15: 48539746 | E15: 004800 | F15: FQC - 02872 | G15: 2007 | H15: Dataworld Computer Center | I15: 60
A16: Windows Professional 10 OLP NL Legalization GG | B16: 43475 | C16: 98279325ZZS1903 | D16: 87482054 | E16: FP099011 | F16: FQC - 09478 | G16: 2010 | H16: Dataworld Computer Center | I16: 4
A17: Windows GGWA - Windows 11 Pro - Legalization Get Genuine - Commercial | B17: 45559 | E17: 20007990 | F17: DG7GMGF0L4TL | G17: 2011 | H17: Dataworld Computer Center | I17: 5
A18: TOTAL | I18: =SUM(I14:I17) -> 93
A20: MICROSOFT OFFICE LICENSES
A21: Office Name | B21: Puchased/Licensed Date | C21: Authorization Number | D21: License Number | E21: Distributor Purchase Order Number | F21: Microsoft Part Number | G21: Version | H21: Vendor | I21: Quantity
A22: MS Office Home & Business 2016 32bit/65bit License | B22: 43696 | C22: N/A | D22: N/A | E22: 56176 | F22: 99994-550,897,203,893,896 | G22: 2016 | H22: Microtrade GCM Corporation | I22: 5
A23: Microsoft Office 2010 Single OPEN 1 Licensed No level | B23: 40687 | C23: 68516159ZZS1305 | D23: 48539745 | E23: 004801 | F23: 021 - 09707 | G23: 2010 | H23: Dataworld Computer Center | I23: 25
A24: TOTAL | I24: =SUM(I22:I23) -> 30
A33: =SUM('Head Office'!D52:E52,'Main Office'!D42:E42,'Jasaan Branch'!D45:E45,'Salay Branch'!D39:E39,'CDO Branch'!D45:E45,'Maramag Branch'!D38:E38,'Gingoog BL'!D33:E33,'Camiguin BL'!D32:E32,'Butuan BL'!D32:E32,'Kibawe BL'!D27:E27) -> 109 | B33: =SUM(I10,I18,I24) -> 175

Sheet Head Office
B2: RBT BANK, INC.
B3: SOFTWARE LICENSE INVENTORY
B4: As of September 2025
B6: HEAD OFFICE
C7: DESIGNATION | D7: USER | E7: ITEM TYPE | F7: OPERATING SYSTEM | G7: LICENSED | H7: OFFICE TOOLS | I7: CLIENT ACCESS | J7: SECTION
B8: 1 | C8: Manager III, Head-HR Section | D8: CENA, Phsyche Joy B. | E8: Laptop | F8: Mac OS | G8: YES | H8: MS Office 365 | I8: Excluded | J8: HR
B9: 2 | C9: AM II, Head-MIS Section | D9: VACALARES, Pepito V. Jr. | E9: Laptop | F9: Win 11Pro OEM 64bit | G9: YES | H9: MS OFFICE STD 2010 | I9: CAL | J9: MIS
B10: 3 | C10: Manager III, Head-Audit Section | D10: BADIC, Emielyn R. | E10: Laptop | F10: Win 11 Pro OEM | G10: YES | H10: MS OFFICE LTSC 2024 | I10: Excluded | J10: Audit
B11: 4 | C11: Manager II, Head-MFU | D11: CARAEL, Virgencita Daisy Q. | E11: Laptop | F11: Win 10 Pro OEM 64bit | G11: YES | H11: OPEN OFFICE/LIBREOFFICE | I11: Excluded | J11: MFU
B12: 5 | C12: AM II, Junior Accountant | D12: ALIDO, Frevie Eve R. | E12: Laptop | F12: Win 10 Pro OEM 64bit | G12: YES | H12: OPEN OFFICE/LIBREOFFICE | I12: Excluded | J12: Accounting
B13: 6 | C13: AVP, Head-Compliance | D13: BAILO, Thesil M. | E13: Laptop | F13: Win 11Pro OEM 64bit | G13: YES | H13: OPEN OFFICE/LIBREOFFICE | I13: Excluded | J13: Compliance
B14: 7 | C14: Administrative Assistant I | D14: PANGAN, Ira Regine M. | E14: Laptop | F14: Win 11Pro OEM 64bit | G14: YES | H14: MS OFFICE LTSC 2021 | I14: Excluded | J14: OP
B15: 8 | C15: Administrative Assistant #2 | D15: PANGAN, Ira Regine M. | E15: Laptop | F15: Win 10 Pro OEM 64bit | G15: YES | H15: MS OFFICE STD 2010 | I15: Excluded | J15: OP
B16: 9 | C16: Accounting Clerk I | D16: EBARLE, Lia | E16: Desktop | F16: Win 10 Pro 64bit | G16: YES | H16: OPEN OFFICE/LIBREOFFICE | I16: Excluded | J16: SME
B17: 10 | C17: SME Account Assistant | D17: GABRIEL, Jomar E. | E17: Laptop | F17: Win 10 Pro OEM 64bit | G17: YES | H17: OPEN OFFICE/LIBREOFFICE | I17: Excluded | J17: SME
B18: 11 | C18: SME Account Assistant | D18: DOMINGUEZ, Jeson T. | E18: Laptop | F18: Win 11Pro OEM 64bit | G18: YES | H18: OPEN OFFICE/LIBREOFFICE | I18: Excluded | J18: SME
B19: 12 | C19: Auditor I #3 | D19: JUMOC, Monique A. | E19: Laptop | F19: Win 10 Pro OEM 64bit | G19: YES | H19: OPEN OFFICE/LIBREOFFICE | I19: Excluded | J19: Audit
... B32: 26 | C32: Business Development Officer | D32: SALUNA, Joel | E32: Laptop | F32: Win 11 Pro OEM | G32: YES | H32: MS OFFICE LTSC 2024 | I32: Excluded | J32: BDO
C34: SUMMARY | D34: OS | E34: MS OFFICE | F34: CAL | H34: MS OFFICE VERSION
C35: No. of Users w/ License | D35: =COUNTIF($G8:$G32,"YES") -> 25 | E35: =COUNTIFS($H8:$H32,"<>",$H8:$H32,"<>OPEN OFFICE/LIBREOFFICE") -> 7 | F35: =COUNTIFS($I8:$I32,"CAL") -> 1 | H35: MS Office 2010 | I35: =COUNTIF($H8:$H32,"*2010") -> 3
C36: No. of Users w/o License | D36: =COUNTIF($G8:$G32,"NO") -> 0 | E36: =COUNTIFS($H8:$H32,"<>",$H8:$H32,"OPEN OFFICE/LIBREOFFICE") -> 18 | F36: =COUNTIFS($I8:$I32,"NONE") -> 0 | H36: MS Office 2016 | I36: =COUNTIF($H8:$H32,"*2016") -> 0
E37: Excluded | F37: =COUNTIF($I8:$I32,"Excluded") -> 24 | H37: MS Office 2021 | I37: =COUNTIF($H8:$H32,"*2021") -> 1
H38: MS Office 2024 | I38: =COUNTIF($H8:$H32,"*2024") -> 2
C39: OS BREAKDOWN | H39: MS Office 365 | I39: =COUNTIF(H8:H32,"*365") -> 1
D40: Laptop | E40: Desktop PC
C41: Windows 11
C42: Home | D42: =COUNTIFS($E8:$E32,"LAPTOP",$F8:$F32,"*11*Home*") -> 0 | E42: =COUNTIFS($E8:$E32,"DESKTOP",$F8:$F32,"*11*Home*") -> 0
C43: Pro | D43: =COUNTIFS($E8:$E32,"LAPTOP",$F8:$F32,"*11*PRO*") -> 6 | E43: =COUNTIFS($E8:$E32,"DESKTOP",$F8:$F32,"*11*PRO*") -> 2
C44: Windows 10
C45: Pro OEM | D45: =COUNTIFS($E8:$E32,"LAPTOP",$F8:$F32,"*10*OEM*") -> 5 | E45: =COUNTIFS($E8:$E32,"DESKTOP",$F8:$F32,"*10*OEM*") -> 0
C46: Pro | D46: =COUNTIFS($E8:$E32,"LAPTOP",$F8:$F32,"*10*",$F8:$F32,"<>*OEM*") -> 1 | E46: =COUNTIFS($E8:$E32,"DESKTOP",$F8:$F32,"*Win 10*",$F8:$F32,"<>*OEM*") -> 7
C47: Windows 8 | D47: =COUNTIFS($E8:$E32,"LAPTOP",$F8:$F32,"*8*") -> 0 | E47: =COUNTIFS($E8:$E32,"DESKTOP",$F8:$F32,"*8*") -> 0 | F47: Note:
C48: Windows 7 | F48: Some Windows 10 Pro (Desktop) were migrated from windows 7 GGWA
C49: Ultimate / Starter | D49: =COUNTIFS($E8:$E32,"LAPTOP",$F8:$F32,"*7*",$F8:$F32,"<>*GGWA*") -> 0 | E49: =COUNTIFS($E8:$E32,"DESKTOP",$F8:$F32,"*7*",$F8:$F32,"<>*GGWA*") -> 0
C50: Pro GGWA | D50: =COUNTIFS($E8:$E32,"LAPTOP",$F8:$F32,"*7*GGWA*") -> 0 | E50: =COUNTIFS($E8:$E32,"DESKTOP",$F8:$F32,"*7*GGWA*") -> 3
C51: TOTAL | D51: =SUM(D41:D50) -> 12 | E51: =SUM(E41:E50) -> 12
D52: =D51+E51 -> 24

Sheet Main Office
B2: RBT BANK, INC.
B3: SOFTWARE LICENSE INVENTORY
B4: ='Head Office'!B4:I4 -> As of September 2025
B6: MAIN OFFICE
B8: DESIGNATION | D8: USER | E8: ITEM TYPE | F8: OPERATING SYSTEM | G8: LICENSED | H8: OFFICE TOOLS | I8: CLIENT ACCESS | J8: SECTION
B9: 1 | C9: Manager I, Head-Main Office | D9: CABOTAJE, Johanna Evan O. | E9: Laptop | F9: Mac OS | G9: YES | H9: MS Office 365 | I9: CAL | J9: Manager
B10: 2 | C10: Loan Supervisor | D10: PADILLA, Leo T. | E10: Desktop | F10: Win 10 Pro | G10: YES | H10: MS OFFICE 2016 | I10: CAL | J10: Accounting
B11: 3 | C11: General Bookkeeper II | D11: ONIO, Ruby Mae B. | E11: Desktop | F11: Win 10 Pro | G11: YES | H11: MS OFFICE STD 2010 | I11: CAL | J11: Accounting
B12: 4 | C12: Cashier I | D12: OBEDENCIO, May Rachel P. | E12: Desktop | F12: Win 10 Pro | G12: YES | H12: MS OFFICE STD 2010 | I12: CAL | J12: Cash
B13: 5 | C13: Assistant Cashier | D13: TUGADE, Emelia V. | E13: Desktop | F13: Win 10 Pro | G13: YES | H13: OPEN OFFICE/LIBREOFFICE | I13: CAL | J13: Cash
B14: 6 | C14: Customer Associate I | D14: ABARRIENTOS, Chiarazol | E14: Desktop | F14: Win 10 Pro | G14: YES | H14: MS OFFICE STD 2010 | I14: NONE | J14: Cash
B15: 7 | C15: Teller I | D15: CAIÑA, Claire Mary L. | E15: Desktop | F15: Win 10 Pro | G15: YES | H15: MS OFFICE STD 2010 | I15: CAL | J15: Cash
B16: 8 | C16: Teller I | D16: MOSTACISA, Jeanny B. | E16: Desktop | F16: Win 10 Pro | G16: YES | H16: MS OFFICE STD 2010 | I16: CAL | J16: Cash
B17: 9 | C17: Loans Bookkeeper I | D17: GAVASAN, Gemma R. | E17: Desktop | F17: Win 10 Pro | G17: YES | H17: OPEN OFFICE/LIBREOFFICE | I17: CAL | J17: Accounting
B18: 10 | C18: Accounting Clerk I | D18: RIVERA, Nicolle Socorro A. | E18: Desktop | F18: Win 10 Pro | G18: YES | H18: OPEN OFFICE/LIBREOFFICE | I18: NONE | J18: Accounting
B19: 11 | C19: Loan Processor II | D19: CASTRO, Darwinda B. | E19: Desktop | F19: Win 10 Pro | G19: YES | H19: OPEN OFFICE/LIBREOFFICE | I19: NONE | J19: Accounting
B20: 13 | C20: Account Officer I | D20: JINAYON,Larry Mar D. | E20: Desktop | F20: Win 10 Pro | G20: YES | H20: OPEN OFFICE/LIBREOFFICE | I20: NONE | J20: Loans
C23: SUMMARY | D23: OS | E23: MS OFFICE | F23: CAL | H23: MS OFFICE VERSION
C24: No. of Users w/ License | D24: =COUNTIF($G9:$G20,"YES") -> 12 | E24: =COUNTIFS($H9:$H20,"<>",$H9:$H20,"<>OPEN OFFICE/LIBREOFFICE") -> 7 | F24: =COUNTIFS($I9:$I20,"CAL") -> 8 | H24: MS Office 2010 | I24: =COUNTIF(H9:H20,"*2010") -> 5
C25: No. of Users w/o License | D25: =COUNTIF($G9:$G20,"NO") -> 0 | E25: =COUNTIFS($H9:$H20,"<>",$H9:$H20,"OPEN OFFICE/LIBREOFFICE") -> 5 | F25: =COUNTIFS($I9:$I20,"NONE") -> 4 | H25: MS Office 2016 | I25: =COUNTIF(H9:H20,"*2016") -> 1
E26: Excluded | F26: =COUNTIFS($I9:$I20,"EXCLUDED") -> 0 | H26: MS Office 2021 | I26: =COUNTIF(H9:H20,"*2021") -> 0
H27: MS Office 2024 | I27: =COUNTIF(H9:H20,"*2024") -> 0
H28: MS Office 365 | I28: =COUNTIF(H9:H20,"*365") -> 1
C29: OS BREAKDOWN
D30: Laptop | E30: Desktop PC
C31: Windows 11
C32: Home | D32: =COUNTIFS($E9:$E20,"LAPTOP",$F9:$F20,"*11*HOME*") -> 0 | E32: =COUNTIFS($E9:$E20,"DESKTOP",$F9:$F20,"*11*HOME*") -> 0
C33: Pro | D33: =COUNTIFS($E9:$E20,"LAPTOP",$F9:$F20,"*11*PRO*") -> 0 | E33: =COUNTIFS($E9:$E20,"DESKTOP",$F9:$F20,"*11*PRO*") -> 0
C34: Windows 10
C35: Pro OEM | D35: =COUNTIFS($E9:$E20,"LAPTOP",$F9:$F20,"*10*OEM*") -> 0 | E35: =COUNTIFS($E9:$E20,"DESKTOP",$F9:$F20,"*10*OEM*") -> 0
C36: Pro | D36: =COUNTIFS($E9:$E20,"LAPTOP",$F9:$F20,"*10*",$F9:$F20,"<>*OEM*") -> 0 | E36: =COUNTIFS($E9:$E20,"DESKTOP",$F9:$F20,"*10*",$F9:$F20,"<>*OEM*") -> 11
C37: Windows 8
C38: Windows 7
C39: Ultimate / Starter | D39: =COUNTIFS($E9:$E20,"LAPTOP",$F9:$F20,"*7*",$F9:$F20,"<>*GGWA*") -> 0 | E39: =COUNTIFS($E9:$E20,"DESKTOP",$F9:$F20,"*7*",$F9:$F20,"<>*GGWA*") -> 0
C40: Pro GGWA | D40: =COUNTIFS($E9:$E20,"LAPTOP",$F9:$F20,"*7*",$F9:$F20,"*GGWA*") -> 0 | E40: =COUNTIFS($E9:$E20,"DESKTOP",$F9:$F20,"*7*",$F9:$F20,"*GGWA*") -> 0
C41: TOTAL | D41: =SUM(D31:D40) -> 0 | E41: =SUM(E31:E40) -> 11
D42: =D41+E41 -> 11

Sheet Jasaan Branch
B2: RBT BANK, INC.
B3: SOFTWARE LICENSE INVENTORY
B4: ='Main Office'!B4:I4 -> As of September 2025
B6: JASAAN BRANCH
B8: DESIGNATION | D8: USER | E8: ITEM TYPE | F8: OPERATING SYSTEM | G8: LICENSED | H8: OFFICE TOOLS | I8: CLIENT ACCESS | J8: SECTION
B9: 1 | C9: Manager III, Head-Jasaan Branch | D9: CALUSA, Rezile O. | E9: Laptop | F9: Windows 11 Pro | G9: YES | H9: MS OFFICE LTSC 2024 | I9: CAL | J9: Manager
B10: 2 | C10: General Bookkeeper II | D10: BULAWAN, Jeprey C. | E10: Desktop | F10: Windows 10 Pro | G10: YES | H10: MS OFFICE STD 2010 | I10: CAL | J10: Accounting
B11: 3 | C11: Cashier II | D11: DUMAPIAS, Melanie E. | E11: Desktop | F11: Windows 7 Pro | G11: YES | H11: MS OFFICE STD 2010 | I11: CAL | J11: Cash
B12: 4 | C12: Assistant Cashier | D12: MACABODBOD, Myrna V. | E12: Desktop | F12: Windows 10 Pro | G12: YES | H12: OPEN OFFICE/LIBREOFFICE | I12: CAL | J12: Cash
B13: 5 | C13: Customer Associate I | D13: MERCADO, Rachel V. | E13: Desktop | F13: Win 10 Pro OEM 64bit | G13: YES | H13: MS OFFICE STD 2010 | I13: CAL | J13: Cash
B14: 6 | C14: Teller I | D14: PABAYO, Nova D. | E14: Desktop | F14: Win 7 Pro GGWA 32bit | G14: YES | H14: MS OFFICE STD 2010 | I14: CAL | J14: Cash
B15: 7 | C15: Teller II | D15: SABAL, Kemberly Ritz N. | E15: Desktop | F15: Win 7 Pro GGWA 32bit | G15: YES | H15: OPEN OFFICE/LIBREOFFICE | I15: CAL | J15: Cash
B16: 8 | C16: Loans Bookkeeper I | D16: POLINAR, Christine Jean B. | E16: Desktop | F16: Windows 10 Pro | G16: YES | H16: OPEN OFFICE/LIBREOFFICE | I16: CAL | J16: Accounting
B17: 9 | C17: Accounting Clerk II | D17: TANGARORANG, Anabella C. | E17: Desktop | F17: Windows 10 Pro | G17: YES | H17: MS OFFICE 2010 STD | I17: CAL | J17: Accounting
B18: 10 | C18: Loan Processor I | D18: MABAYLAN, Shaira E. | E18: Desktop | F18: Windows 10 Pro | G18: YES | H18: OPEN OFFICE/LIBREOFFICE | I18: NONE | J18: Accounting
B19: 11 | C19: Account Officer | D19: BUCAG, Pio | E19: Desktop | F19: Windows 10 Pro | G19: YES | H19: MS OFFICE 2016 | I19: NONE | J19: Loans
B20: 12 | C20: Loan Supervisor | D20: LOBUSTA, Ma. Glenda S. | E20: Desktop | F20: Windows 10 Pro | G20: YES | H20: OPEN OFFICE/LIBREOFFICE | I20: CAL | J20: Loans
... B25: 17 | C25: CIC PC | D25: MIS Section | E25: Desktop | F25: Win 7 Pro GGWA 32bit | G25: YES | H25: OPEN OFFICE/LIBREOFFICE | I25: Excluded | J25: MIS
C28: SUMMARY | D28: OS | E28: MS OFFICE | F28: CAL | H28: MS OFFICE VERSION
C29: No. of Users w/ License | D29: =COUNTIF($G9:$G25,"YES") -> 17 | E29: =COUNTIFS($H9:$H25,"<>",$H9:$H25,"<>OPEN OFFICE/LIBREOFFICE") -> 7 | F29: =COUNTIFS($I9:$I25,"CAL") -> 11 | H29: MS Office 2010 | I29: =COUNTIF(H9:H25,"*2010") -> 4
C30: No. of Users w/o License | D30: =COUNTIF($G9:$G25,"NO") -> 0 | E30: =COUNTIFS($H9:$H25,"<>",$H9:$H25,"OPEN OFFICE/LIBREOFFICE") -> 10 | F30: =COUNTIFS($I9:$I25,"NONE") -> 4 | H30: MS Office 2016 | I30: =COUNTIF(H9:H25,"*2016") -> 1
E31: Excluded | F31: =COUNTIFS($I9:$I25,"EXCLUDED") -> 2 | H31: MS Office 2021 | I31: =COUNTIF(H9:H25,"*2021") -> 0
H32: MS Office 2024 | I32: =COUNTIF(H9:H25,"*2024") -> 1
C33: OS BREAKDOWN
D34: Laptop | E34: Desktop PC
C35: Windows 11
C36: Home | D36: =COUNTIFS($E9:$E25,"LAPTOP",$F9:$F25,"*11*HOME*") -> 0 | E36: =COUNTIFS($E9:$E25,"DESKTOP",$F9:$F25,"*11*HOME*") -> 0
C37: Pro | D37: =COUNTIFS($E9:$E25,"LAPTOP",$F9:$F25,"*11*PRO*") -> 1 | E37: =COUNTIFS($E9:$E25,"DESKTOP",$F9:$F25,"*11*PRO*") -> 0
C38: Windows 10
C39: Pro OEM | D39: =COUNTIFS($E9:$E25,"LAPTOP",$F9:$F25,"*10*OEM*") -> 0 | E39: =COUNTIFS($E9:$E25,"DESKTOP",$F9:$F25,"*10*OEM*") -> 1
C40: Pro | D40: =COUNTIFS($E9:$E25,"LAPTOP",$F9:$F25,"*10*",$F9:$F25,"<>*OEM*") -> 0 | E40: =COUNTIFS($E9:$E25,"DESKTOP",$F9:$F25,"*10*",$F9:$F25,"<>*OEM*") -> 7
C41: Windows 7
C42: Ultimate / Starter | D42: =COUNTIFS($E9:$E25,"LAPTOP",$F9:$F25,"*7*",$F9:$F25,"<>*GGWA*") -> 0 | E42: =COUNTIFS($E9:$E25,"DESKTOP",$F9:$F25,"*7*",$F9:$F25,"<>*GGWA*") -> 1
C43: Pro GGWA | D43: =COUNTIFS($E9:$E25,"LAPTOP",$F9:$F25,"*7*",$F9:$F25,"*GGWA*") -> 0 | E43: =COUNTIFS($E9:$E25,"DESKTOP",$F9:$F25,"*7*",$F9:$F25,"*GGWA*") -> 7
C44: TOTAL | D44: =SUM(D35:D43) -> 1 | E44: =SUM(E35:E43) -> 16
D45: =D44+E44 -> 17

Sheet Salay Branch
B2: RBT BANK, INC.
B3: SOFTWARE LICENSE INVENTORY
B4: ='Main Office'!B4:I4 -> As of September 2025
B6: SALAY BRANCH
B8: DESIGNATION | D8: USER | E8: ITEM TYPE | F8: OPERATING SYSTEM | G8: LICENSED | H8: OFFICE TOOLS | I8: CLIENT ACCESS | J8: SECTION
B9: 1 | C9: Manager I, Head-Salay Branch | D9: CASIÑO, Kathrine N. | E9: Laptop | F9: Windows 11 Home | G9: YES | H9: OPEN OFFICE/LIBREOFFICE | I9: CAL | J9: Manager
B10: 2 | C10: Loan Supervisor II | D10: MABALE, Vic L. | E10: Desktop | F10: Windows 10 Pro | G10: YES | H10: MS OFFICE 2016 | I10: CAL | J10: Loans
B11: 3 | C11: General Bookkeeper I | D11: LAMAYON, Unity C. | E11: Desktop | F11: Win 7 Pro GGWA | G11: YES | H11: MS OFFICE STD 2010 | I11: CAL | J11: Accounting
B12: 4 | C12: Cashier I | D12: KIONISALA, Jenny Ve P. | E12: Desktop | F12: Win 10 | G12: YES | H12: MS OFFICE STD 2010 | I12: CAL | J12: Cash
B13: 5 | C13: Customer Associate I | D13: ALIDO, Alleah B. | E13: Desktop | F13: Windows 10 Pro | G13: YES | H13: MS OFFICE STD 2010 | I13: CAL | J13: Cash
B14: 6 | C14: Teller II | D14: ACOBO, Jucinde L. | E14: Desktop | F14: Win 10 | G14: YES | H14: MS OFFICE STD 2010 | I14: CAL | J14: Cash
B15: 7 | C15: Teller III | D15: TACANDONG, Sheila May T. | E15: Desktop | F15: Win 10 | G15: YES | H15: OPEN OFFICE/LIBREOFFICE | I15: CAL | J15: Cash
B16: 8 | C16: Loans Bookkeeper I | D16: PORAL, Edgar E. Jr. | E16: Desktop | F16: Win 10 | G16: YES | H16: OPEN OFFICE/LIBREOFFICE | I16: CAL | J16: Accounting
B17: 9 | C17: Loan Processor I | D17: CABUSOG, Karen Mae M. | E17: Desktop | F17: Win 7 Pro GGWA | G17: YES | H17: OPEN OFFICE/LIBREOFFICE | I17: NONE | J17: Accounting
B18: 10 | C18: MFU Account Officer II | D18: GAYLOA, Rodulfo A. Jr. | E18: Desktop | F18: Win 10 | G18: YES | H18: OPEN OFFICE/LIBREOFFICE | I18: NONE | J18: Loans
B19: 11 | C19: Account Officer II | D19: CADELIÑA, Rico E. | E19: Desktop | F19: Win 7 Pro GGWA | G19: YES | H19: OPEN OFFICE/LIBREOFFICE | I19: NONE | J19: Loans
C22: SUMMARY | D22: OS | E22: MS OFFICE | F22: CAL | H22: MS OFFICE VERSION
C23: No. of Users w/ License | D23: =COUNTIF($G9:$G19,"YES") -> 11 | E23: =COUNTIFS($H9:$H19,"<>",$H9:$H19,"<>OPEN OFFICE/LIBREOFFICE") -> 5 | F23: =COUNTIFS($I9:$I19,"CAL") -> 8 | H23: MS Office 2010 | I23: =COUNTIF(H9:H19,"*2010") -> 4
C24: No. of Users w/o License | D24: =COUNTIF($G9:$G19,"NO") -> 0 | E24: =COUNTIFS($H9:$H19,"<>",$H9:$H19,"OPEN OFFICE/LIBREOFFICE") -> 6 | F24: =COUNTIFS($I9:$I19,"NONE") -> 3 | H24: MS Office 2016 | I24: =COUNTIF(H9:H19,"*2016") -> 1
E25: Excluded | F25: =COUNTIFS($I9:$I19,"EXCLUDED") -> 0 | H25: MS Office 2021 | I25: =COUNTIF(H9:H19,"*2021") -> 0
H26: MS Office 2024 | I26: =COUNTIF(H9:H19,"*2024") -> 0
C27: OS BREAKDOWN
D28: Laptop | E28: Desktop PC
C29: Windows 11
C30: Home | D30: =COUNTIFS($E9:$E19,"LAPTOP",$F9:$F19,"*11*HOME*") -> 1 | E30: =COUNTIFS($E9:$E19,"DESKTOP",$F9:$F19,"*11*HOME*") -> 0
C31: Pro | D31: =COUNTIFS($E9:$E19,"LAPTOP",$F9:$F19,"*11*PRO*") -> 0 | E31: =COUNTIFS($E9:$E19,"DESKTOP",$F9:$F19,"*11*PRO*") -> 0
C32: Windows 10
C33: Pro OEM | D33: =COUNTIFS($E9:$E19,"LAPTOP",$F9:$F19,"*10*OEM*") -> 0 | E33: =COUNTIFS($E9:$E19,"DESKTOP",$F9:$F19,"*10*OEM*") -> 0
C34: Pro | D34: =COUNTIFS($E9:$E19,"LAPTOP",$F9:$F19,"*10*",$F9:$F19,"<>*OEM*") -> 0 | E34: =COUNTIFS($E9:$E19,"DESKTOP",$F9:$F19,"*10*",$F9:$F19,"<>*OEM*") -> 7
C35: Windows 7
C36: Ultimate / Starter | D36: =COUNTIFS($E9:$E19,"LAPTOP",$F9:$F19,"*7*",$F9:$F19,"<>*GGWA*") -> 0 | E36: =COUNTIFS($E9:$E19,"DESKTOP",$F9:$F19,"*7*",$F9:$F19,"<>*GGWA*") -> 0
C37: Pro GGWA | D37: =COUNTIFS($E9:$E19,"LAPTOP",$F9:$F19,"*7*",$F9:$F19,"*GGWA*") -> 0 | E37: =COUNTIFS($E9:$E19,"DESKTOP",$F9:$F19,"*7*",$F9:$F19,"*GGWA*") -> 3
C38: TOTAL | D38: =SUM(D29:D37) -> 1 | E38: =SUM(E29:E37) -> 10
D39: =D38+E38 -> 11

Sheet CDO Branch
B2: RBT BANK, INC.
B3: SOFTWARE LICENSE INVENTORY
B4: ='Main Office'!B4:I4 -> As of September 2025
B6: CDO BRANCH
B8: DESIGNATION | D8: USER | E8: ITEM TYPE | F8: OPERATING SYSTEM | G8: LICENSED | H8: OFFICE TOOLS | I8: CLIENT ACCESS | J8: SECTION
B9: 1 | C9: Manager II, Head-CDO Branch | D9: SARAUS, Kathy E. | E9: Laptop | F9: Mac OS | G9: YES | H9: MS Office 365 | I9: CAL | J9: Manager
B10: 2 | C10: Loan Officer I | D10: DAHILOG, Brian M. | E10: Desktop | F10: Win 7 Pro GGWA | G10: YES | H10: MS OFFICE 2016 | I10: CAL | J10: Loans
B11: 3 | C11: General Bookkeeper II | D11: MANSEGUIAO, Micheluo B. | E11: Desktop | F11: Win 10 Pro | G11: YES | H11: OPEN OFFICE/LIBREOFFICE | I11: CAL | J11: Accounting
B12: 4 | C12: Assistant Cashier | D12: SUNOT, Venus P. | E12: Desktop | F12: Win 11 Pro | G12: YES | H12: MS OFFICE STD 2010 | I12: CAL | J12: Cash
B13: 5 | C13: Account Officer I (former NACPC) | D13: Pomada, Boyet | E13: Desktop | F13: Win 7 Pro GGWA | G13: YES | H13: OPEN OFFICE/LIBREOFFICE | I13: NONE | J13: Cash
B14: 6 | C14: Teller #1 | D14: DAEL, Christine Julie Jane N. | E14: Desktop | F14: Win 10 Pro | G14: YES | H14: MS OFFICE STD 2010 | I14: CAL | J14: Cash
B15: 7 | C15: Teller #2 | D15: VILLADORES, Cristy J. | E15: Desktop | F15: Win 11 Pro | G15: YES | H15: MS OFFICE STD 2010 | I15: CAL | J15: Cash
B16: 8 | C16: Customer Associate | D16: DUMAGSA, Emalyn | E16: Desktop | F16: Win 10 Pro | G16: YES | H16: MS OFFICE 2016 | J16: Cash
B17: 9 | C17: Loans Bookkeeper I | D17: AGBU, Marie Bernadeth E. | E17: Desktop | F17: Win 11 Pro | G17: YES | H17: OPEN OFFICE/LIBREOFFICE | I17: CAL | J17: Accounting
B18: 10 | C18: Accounting Clerk I | D18: ASENTISTA, Aisa Jane C. | E18: Desktop | F18: Win 10 Pro | G18: YES | H18: MS OFFICE STD 2010 | I18: NONE | J18: Accounting
B19: 11 | C19: Loan Processor #2 | D19: BERNALES,Maribel | E19: Desktop | F19: Win 10 Pro | G19: YES | H19: MS OFFICE 2016 | I19: CAL | J19: Accounting
B20: 12 | C20: Loan Processor #1 | D20: MAHUSAY, Roxan T. | E20: Desktop | F20: Win 10 Pro | G20: YES | H20: MS OFFICE 2016 | I20: NONE | J20: Accounting
B21: 13 | C21: O/L Supervisor | D21: BASUBAS, Cirane C. | E21: Desktop | F21: Win 11 Pro | G21: YES | H21: MS OFFICE 2016 | I21: CAL | J21: Loans
B22: 14 | C22: Account Officer I | D22: SARAUS, Jezzrel P. | E22: Desktop | F22: Win 7 Pro GGWA | G22: YES | H22: OPEN OFFICE/LIBREOFFICE | I22: NONE | J22: Loans
B23: 15 | C23: Account Officer I | D23: PACLAR, Pepper A. | E23: Desktop | F23: Win 11 Pro OEM | G23: YES | H23: MS OFFICE LTSC 2024 | I23: NONE | J23: Loans
B24: 16 | C24: Office Assistant (CDO-BLU) | D24: OÑEZ, Arniel H. | E24: Desktop | F24: Win 7 Pro GGWA | G24: YES | H24: OPEN OFFICE/LIBREOFFICE | I24: Excluded | J24: Accounting
B25: 17 | C25: AO-OL (Iligan-BLU) | D25: LESPANA, Remark I | E25: Desktop | F25: Win 7 Pro GGWA | G25: YES | H25: OPEN OFFICE/LIBREOFFICE | I25: Excluded | J25: Accounting
C28: SUMMARY | D28: OS | E28: MS OFFICE | F28: CAL | H28: MS OFFICE VERSION
C29: No. of Users w/ License | D29: =COUNTIF($G9:$G25,"YES") -> 17 | E29: =COUNTIFS($H9:$H25,"<>",$H9:$H25,"<>OPEN OFFICE/LIBREOFFICE") -> 11 | F29: =COUNTIFS($I9:$I25,"CAL") -> 9 | H29: MS Office 2010 | I29: =COUNTIF(H9:H25,"*2010") -> 4
C30: No. of Users w/o License | D30: =COUNTIF($G9:$G25,"NO") -> 0 | E30: =COUNTIFS($H9:$H25,"<>",$H9:$H25,"OPEN OFFICE/LIBREOFFICE") -> 6 | F30: =COUNTIFS($I9:$I25,"NONE") -> 5 | H30: MS Office 2016 | I30: =COUNTIF(H9:H25,"*2016") -> 5
E31: Excluded | F31: =COUNTIFS($I9:$I25,"EXCLUDED") -> 2 | H31: MS Office 2021 | I31: =COUNTIF(H9:H25,"*2021") -> 0
H32: MS Office 2024 | I32: =COUNTIF(H9:H25,"*2024") -> 1
H33: MS Office 365 | I33: =COUNTIF(H9:H25,"*365") -> 1
C34: OS BREAKDOWN
D35: Laptop | E35: Desktop PC
C36: Windows 11
C37: Home | D37: =COUNTIFS($E9:$E25,"LAPTOP",$F9:$F25,"*11*HOME*") -> 0 | E37: =COUNTIFS($E9:$E25,"DESKTOP",$F9:$F25,"*11*HOME*") -> 0
C38: Pro | D38: =COUNTIFS($E9:$E25,"LAPTOP",$F9:$F25,"*11*PRO*") -> 0 | E38: =COUNTIFS($E9:$E25,"DESKTOP",$F9:$F25,"*11*PRO*") -> 5
C39: Windows 10
C40: Pro OEM | D40: =COUNTIFS($E9:$E25,"LAPTOP",$F9:$F25,"*10*OEM*") -> 0 | E40: =COUNTIFS($E9:$E25,"DESKTOP",$F9:$F25,"*10*OEM*") -> 0
C41: Pro | D41: =COUNTIFS($E9:$E25,"LAPTOP",$F9:$F25,"*10*",$F9:$F25,"<>*OEM*") -> 0 | E41: =COUNTIFS($E9:$E25,"DESKTOP",$F9:$F25,"*10*",$F9:$F25,"<>*OEM*") -> 6
C42: Windows 7 | F42: Note:
C43: Pro GGWA | D43: =COUNTIFS($E9:$E25,"LAPTOP",$F9:$F25,"*7*",$F9:$F25,"*GGWA*") -> 0 | E43: =COUNTIFS($E9:$E25,"DESKTOP",$F9:$F25,"*7*",$F9:$F25,"*GGWA*") -> 5 | F43: Some Windows 10 Pro (Desktop) were migrated from windows 7 GGWA
C44: TOTAL | D44: =SUM(D36:D43) -> 0 | E44: =SUM(E36:E43) -> 16
D45: =D44+E44 -> 16

Sheet Maramag Branch
B2: RBT BANK, INC.
B3: SOFTWARE LICENSE INVENTORY
B4: ='Main Office'!B4:I4 -> As of September 2025
B6: MARAMAG BRANCH
C8: DESIGNATION | D8: USER | E8: ITEM TYPE | F8: OPERATING SYSTEM | G8: LICENSED | H8: OFFICE TOOLS | I8: CLIENT ACCESS | J8: SECTION
B9: 1 | C9: Manager I, Head-Maramag Branch | D9: BAJAO, Edward G. | E9: Laptop | F9: Windows 11 Home 64bit | G9: YES | H9: OPEN OFFICE/LIBREOFFICE | I9: CAL | J9: Manager
B10: 2 | C10: Loan Supervisor | D10: GABALES, Christian L. | E10: Desktop | F10: Windows 10 Pro 64bit | G10: YES | H10: MS OFFICE 2016 | I10: NONE | J10: Loans
B11: 3 | C11: General Bookkeeper I | D11: LAO, Lester Terex M. | E11: Desktop | F11: Windows 7 Home 32bit | G11: YES | H11: MS OFFICE STD 2010 | I11: CAL | J11: Accounting
B12: 4 | C12: Cashier | D12: CABUNILAS, Julie Ann A. | E12: Desktop | F12: Win 7 Pro GGWA 32bit | G12: YES | H12: MS OFFICE STD 2010 | I12: CAL | J12: Cash
B13: 5 | C13: Teller | D13: Tiberio, Arjean. | E13: Desktop | F13: Windows 10 Pro 64bit | G13: YES | H13: MS OFFICE STD 2010 | I13: CAL | J13: Cash
B14: 6 | C14: Customer Associate | D14: BANHAW, Jeniffer L. | E14: Desktop | F14: Win 10 Pro 64bit | G14: YES | H14: OPEN OFFICE/LIBREOFFICE | I14: NONE | J14: CAsh
B15: 7 | C15: Loans Bookkeeper | D15: MAGDALE,Janeth L. | E15: Desktop | F15: Win 11 Pro 64bit | G15: YES | H15: OPEN OFFICE/LIBREOFFICE | I15: CAL | J15: Accounting
B16: 8 | C16: Loan Processor I | D16: PAMAYLAON, Jessavyl M. | E16: Desktop | F16: Win 7 Pro GGWA 32bit | G16: YES | H16: OPEN OFFICE/LIBREOFFICE | I16: NONE | J16: Accounting
B17: 9 | C17: Account Officer II | D17: VALIENTE, Regidor A. | E17: Desktop | F17: Win 7 Pro GGWA 32bit | G17: YES | H17: OPEN OFFICE/LIBREOFFICE | I17: NONE | J17: Loans
C20: SUMMARY | D20: OS | E20: MS OFFICE | F20: CAL | H20: MS OFFICE VERSION
C21: No. of Users w/ License | D21: =COUNTIF($G9:$G17,"YES") -> 9 | E21: =COUNTIFS($H9:$H17,"<>",$H9:$H17,"<>OPEN OFFICE/LIBREOFFICE") -> 4 | F21: =COUNTIFS($I9:$I17,"CAL") -> 5 | H21: MS Office 2010 | I21: =COUNTIF(H9:H17,"*2010") -> 3
C22: No. of Users w/o License | D22: =COUNTIF($G9:$G17,"NO") -> 0 | E22: =COUNTIFS($H9:$H17,"<>",$H9:$H17,"OPEN OFFICE/LIBREOFFICE") -> 5 | F22: =COUNTIFS($I9:$I17,"NONE") -> 4 | H22: MS Office 2016 | I22: =COUNTIF(H9:H17,"*2016") -> 1
E23: Excluded | F23: =COUNTIFS($I9:$I17,"EXCLUDED") -> 0 | H23: MS Office 2021 | I23: =COUNTIF(H9:H17,"*2021") -> 0
H24: MS Office 2024 | I24: =COUNTIF(H9:H17,"*2024") -> 0
C26: OS BREAKDOWN
D27: Laptop | E27: Desktop PC
C28: Windows 11
C29: Home | D29: =COUNTIFS($E9:$E17,"LAPTOP",$F9:$F17,"*11*HOME*") -> 1 | E29: =COUNTIFS($E9:$E17,"DESKTOP",$F9:$F17,"*11*HOME*") -> 0
C30: Pro | D30: =COUNTIFS($E9:$E17,"LAPTOP",$F9:$F17,"*11*PRO*") -> 0 | E30: =COUNTIFS($E9:$E17,"DESKTOP",$F9:$F17,"*11*PRO*") -> 1
C31: Windows 10
C32: Pro OEM | D32: =COUNTIFS($E9:$E17,"LAPTOP",$F9:$F17,"*10*OEM*") -> 0 | E32: =COUNTIFS($E9:$E17,"DESKTOP",$F9:$F17,"*10*OEM*") -> 0
C33: Pro | D33: =COUNTIFS($E9:$E17,"LAPTOP",$F9:$F17,"*10*",$F9:$F17,"<>*OEM*") -> 0 | E33: =COUNTIFS($E9:$E17,"DESKTOP",$F9:$F17,"*10*",$F9:$F17,"<>*OEM*") -> 3
C34: Windows 7
C35: Starter | D35: =COUNTIFS($E9:$E17,"LAPTOP",$F9:$F17,"*7*",$F9:$F17,"<>*GGWA*") -> 0 | E35: =COUNTIFS($E9:$E17,"DESKTOP",$F9:$F17,"*7*",$F9:$F17,"<>*GGWA*") -> 1
C36: Pro GGWA | D36: =COUNTIFS($E9:$E17,"LAPTOP",$F9:$F17,"*7*",$F9:$F17,"*GGWA*") -> 0 | E36: =COUNTIFS($E9:$E17,"DESKTOP",$F9:$F17,"*7*",$F9:$F17,"*GGWA*") -> 3
C37: TOTAL | D37: =SUM(D28:D36) -> 1 | E37: =SUM(E28:E36) -> 8
D38: =D37+E37 -> 9

Sheet Gingoog BL
B2: RBT BANK, INC.
B3: SOFTWARE LICENSE INVENTORY
B4: ='Main Office'!B4:I4 -> As of September 2025
B6: GINGOOG BLU
B8: DESIGNATION | D8: USER | E8: ITEM TYPE | F8: OPERATING SYSTEM | G8: LICENSED | H8: OFFICE TOOLS | I8: CLIENT ACCESS | J8: SECTION
B9: 1 | C9: Loan Officer, Branch Lite Head | D9: COSTUDIO, Grace L. | E9: Desktop | F9: Win10 Pro | G9: YES | H9: OPEN OFFICE/LIBREOFFICE | I9: Excluded | J9: Loans
B10: 2 | C10: Accounting Clerk I | D10: ESPANTALEON, Lyca K. | E10: Desktop | F10: Win 7 Pro GGWA | G10: YES | H10: OPEN OFFICE/LIBREOFFICE | I10: Excluded | J10: Accounting
B11: 3 | C11: Loan Processor I | D11: ARCANSIS, Zyrabelle A. | E11: Desktop | F11: Win 7 Pro GGWA | G11: YES | H11: OPEN OFFICE/LIBREOFFICE | I11: Excluded | J11: Accounting
B12: 4 | C12: Office Associate | D12: TIMOTEO, Lester Mae C. | E12: Desktop | F12: Win 7 Pro GGWA | G12: YES | H12: OPEN OFFICE/LIBREOFFICE | I12: Excluded | J12: Cash
B13: 5 | C13: Customer Associate | D13: RATILLA, Jobelle Q | E13: Desktop | F13: Win10 Pro | G13: YES | H13: OPEN OFFICE/LIBREOFFICE | I13: Excluded | J13: Cash
B14: 6 | C14: Account Officer I | D14: CONDEZA, Miguel M. | E14: Desktop | F14: Win 10 Pro OEM 64bit | G14: YES | H14: OPEN OFFICE/LIBREOFFICE | I14: Excluded | J14: Loans
B15: 7 | C15: Account Officer I | D15: POLINAR, Alby Y. | E15: Desktop | F15: Win 10 Pro | G15: YES | H15: OPEN OFFICE/LIBREOFFICE | I15: Excluded | J15: Loans
C17: SUMMARY | D17: OS | E17: MS OFFICE | F17: CAL | H17: MS OFFICE VERSION
C18: No. of Users w/ License | D18: =COUNTIF($G9:$G15,"YES") -> 7 | E18: =COUNTIFS($H9:$H15,"<>",$H9:$H15,"<>OPEN OFFICE/LIBREOFFICE") -> 0 | F18: =COUNTIFS($I9:$I15,"CAL") -> 0 | H18: MS Office 2010 | I18: =COUNTIF(H9:H15,"*2010") -> 0
C19: No. of Users w/o License | D19: =COUNTIF($G9:$G15,"NO") -> 0 | E19: =COUNTIFS($H9:$H15,"<>",$H9:$H15,"OPEN OFFICE/LIBREOFFICE") -> 7 | F19: =COUNTIFS($I9:$I15,"NONE") -> 0 | H19: MS Office 2016 | I19: =COUNTIF(H9:H15,"*2016") -> 0
E20: Excluded | F20: =COUNTIFS($I9:$I15,"EXCLUDED") -> 7 | H20: MS Office 2021 | I20: =COUNTIF(H9:H15,"*2021") -> 0
H21: MS Office 2024 | I21: =COUNTIF(H9:H15,"*2024") -> 0
C22: OS BREAKDOWN
D23: Laptop | E23: Desktop PC
C24: Windows 11
C25: Home | D25: =COUNTIFS($E9:$E15,"LAPTOP",$F9:$F15,"*11*HOME*") -> 0 | E25: =COUNTIFS($E9:$E15,"DESKTOP",$F9:$F15,"*11*HOME*") -> 0
C26: Pro | D26: =COUNTIFS($E9:$E15,"LAPTOP",$F9:$F15,"*11*PRO*") -> 0 | E26: =COUNTIFS($E9:$E15,"DESKTOP",$F9:$F15,"*11*PRO*") -> 0
C27: Windows 10
C28: Pro OEM | D28: =COUNTIFS($E9:$E15,"LAPTOP",$F9:$F15,"*10*OEM*") -> 0 | E28: =COUNTIFS($E9:$E15,"DESKTOP",$F9:$F15,"*10*OEM*") -> 1
C29: Pro | D29: =COUNTIFS($E9:$E15,"LAPTOP",$F9:$F15,"*10*",$F9:$F15,"<>*OEM*") -> 0 | E29: =COUNTIFS($E9:$E15,"DESKTOP",$F9:$F15,"*10*",$F9:$F15,"<>*OEM*") -> 3
C30: Windows 7
C31: Pro GGWA | D31: =COUNTIFS($E9:$E15,"LAPTOP",$F9:$F15,"*7*",$F9:$F15,"*GGWA*") -> 0 | E31: =COUNTIFS($E9:$E15,"DESKTOP",$F9:$F15,"*7*",$F9:$F15,"*GGWA*") -> 3
C32: TOTAL | D32: =SUM(D24:D31) -> 0 | E32: =SUM(E24:E31) -> 7
D33: =D32+E32 -> 7

Sheet Camiguin BL
B2: RBT BANK, INC.
B3: SOFTWARE LICENSE INVENTORY
B4: ='Main Office'!B4:I4 -> As of September 2025
B6: CAMIGUIN BLU
B8: DESIGNATION | D8: USER | E8: ITEM TYPE | F8: OPERATING SYSTEM | G8: LICENSED | H8: OFFICE TOOLS | I8: CLIENT ACCESS | J8: SECTION
B9: 1 | C9: Loan Supervisor I / BLU Head | D9: TABAMO, Josephine C. | E9: Desktop | F9: Win 10 Pro OEM 64bit | G9: YES | H9: OPEN OFFICE/LIBREOFFICE | I9: Excluded | J9: Loans
B10: 2 | C10: Accounting Clerk I | D10: OCANG, Luta A. | E10: Desktop | F10: Win 7 Pro GGWA | G10: YES | H10: OPEN OFFICE/LIBREOFFICE | I10: Excluded | J10: Accounting
B11: 3 | C11: Office Associate | D11: NAMOC, Angel Mae | E11: Desktop | F11: Win 7 Pro GGWA | G11: YES | H11: OPEN OFFICE/LIBREOFFICE | I11: Excluded | J11: Cash
B12: 4 | C12: Account Officer I | D12: BORRES, Rodolfo Jr. C. | E12: Desktop | F12: Win 10 Pro OEM 64bit | G12: YES | H12: OPEN OFFICE/LIBREOFFICE | I12: Excluded | J12: Loans
C15: SUMMARY | D15: OS | E15: MS OFFICE | F15: CAL | H15: MS OFFICE VERSION
C16: No. of Users w/ License | D16: =COUNTIF($G9:$G12,"YES") -> 4 | E16: =COUNTIFS($H9:$H12,"<>",$H9:$H12,"<>OPEN OFFICE/LIBREOFFICE") -> 0 | F16: =COUNTIFS($I9:$I12,"CAL") -> 0 | H16: MS Office 2010 | I16: =COUNTIF(H9:H12,"*2010") -> 0
C17: No. of Users w/o License | D17: =COUNTIF($G9:$G12,"NO") -> 0 | E17: =COUNTIFS($H9:$H12,"<>",$H9:$H12,"OPEN OFFICE/LIBREOFFICE") -> 4 | F17: =COUNTIFS($I9:$I12,"NONE") -> 0 | H17: MS Office 2016 | I17: =COUNTIF(H9:H12,"*2016") -> 0
E18: Excluded | F18: =COUNTIFS($I9:$I12,"EXCLUDED") -> 4 | H18: MS Office 2021 | I18: =COUNTIF(H9:H12,"*2021") -> 0
H19: MS Office 2024 | I19: =COUNTIF(H9:H12,"*2024") -> 0
C20: OS BREAKDOWN
D22: Laptop | E22: Desktop PC
C23: Windows 11
C24: Home | D24: =COUNTIFS($E9:$E12,"LAPTOP",$F9:$F12,"*11*HOME*") -> 0 | E24: =COUNTIFS($E9:$E12,"DESKTOP",$F9:$F12,"*11*HOME*") -> 0
C25: Pro | D25: =COUNTIFS($E9:$E12,"LAPTOP",$F9:$F12,"*11*PRO*") -> 0 | E25: =COUNTIFS($E9:$E12,"DESKTOP",$F9:$F12,"*11*PRO*") -> 0
C26: Windows 10
C27: Pro OEM | D27: =COUNTIFS($E9:$E12,"LAPTOP",$F9:$F12,"*10*OEM*") -> 0 | E27: =COUNTIFS($E9:$E12,"DESKTOP",$F9:$F12,"*10*OEM*") -> 2
C28: Pro | D28: =COUNTIFS($E9:$E12,"LAPTOP",$F9:$F12,"*10*",$F9:$F12,"<>*OEM*") -> 0 | E28: =COUNTIFS($E9:$E12,"DESKTOP",$F9:$F12,"*10*",$F9:$F12,"<>*OEM*") -> 0
C29: Windows 7
C30: Pro GGWA | D30: =COUNTIFS($E9:$E12,"LAPTOP",$F9:$F12,"*7*",$F9:$F12,"*GGWA*") -> 0 | E30: =COUNTIFS($E9:$E12,"DESKTOP",$F9:$F12,"*7*",$F9:$F12,"*GGWA*") -> 2
C31: TOTAL | D31: =SUM(D23:D30) -> 0 | E31: =SUM(E23:E30) -> 4
D32: =D31+E31 -> 4

Sheet Butuan BL
B2: RBT BANK, INC.
B3: SOFTWARE LICENSE INVENTORY
B4: ='Main Office'!B4:I4 -> As of September 2025
B6: BUTUAN BLU
B8: DESIGNATION | D8: USER | E8: ITEM TYPE | F8: OPERATING SYSTEM | G8: LICENSED | H8: OFFICE TOOLS | I8: CLIENT ACCESS | J8: SECTION
B9: 1 | C9: Acting BLU HEAD | D9: OYAN, Michelle M. | E9: Laptop | F9: Win 7 Pro GGWA | G9: YES | H9: OPEN OFFICE/LIBREOFFICE | I9: Excluded | J9: Loans
B10: 2 | C10: Office Associate | D10: HONREJAS, Princess Jane A. | E10: Desktop | F10: Win 7 Pro GGWA | G10: YES | H10: OPEN OFFICE/LIBREOFFICE | I10: Excluded | J10: Cash
B11: 3 | C11: Loans Bookkeeper / Accounting | D11: MACARAYO, Clark | E11: Desktop | F11: Win 11 Pro | G11: YES | H11: OPEN OFFICE/LIBREOFFICE | I11: Excluded | J11: Accounting
B12: 4 | C12: Loans Processor | D12: GALDIANO, Georly Mae | E12: Desktop | F12: Win 10 Pro | G12: YES | H12: OPEN OFFICE/LIBREOFFICE | I12: Excluded | J12: Loans
B13: 5 | C13: Account Officer | D13: SUMAGANG, Junmar | E13: Desktop | F13: Win 7 Pro GGWA | G13: YES | H13: OPEN OFFICE/LIBREOFFICE | I13: Excluded | J13: Loans
C16: SUMMARY | D16: OS | E16: MS OFFICE | F16: CAL | H16: MS OFFICE VERSION
C17: No. of Users w/ License | D17: =COUNTIF($G9:$G13,"YES") -> 5 | E17: =COUNTIFS($H9:$H13,"<>",$H9:$H13,"<>OPEN OFFICE/LIBREOFFICE") -> 0 | F17: =COUNTIFS($I9:$I13,"CAL") -> 0 | H17: MS Office 2010 | I17: =COUNTIF(H9:H13,"*2010") -> 0
C18: No. of Users w/o License | D18: =COUNTIF($G9:$G13,"NO") -> 0 | E18: =COUNTIFS($H9:$H13,"<>",$H9:$H13,"OPEN OFFICE/LIBREOFFICE") -> 5 | F18: =COUNTIFS($I9:$I13,"NONE") -> 0 | H18: MS Office 2016 | I18: =COUNTIF(H9:H13,"*2016") -> 0
E19: Excluded | F19: =COUNTIFS($I9:$I13,"EXCLUDED") -> 5 | H19: MS Office 2021 | I19: =COUNTIF(H9:H13,"*2021") -> 0
H20: MS Office 2024 | I20: =COUNTIF(H9:H13,"*2024") -> 0
C21: OS BREAKDOWN
D22: Laptop | E22: Desktop PC
C23: Windows 11
C24: Home | D24: =COUNTIFS($E9:$E13,"LAPTOP",$F9:$F13,"*11*HOME*") -> 0 | E24: =COUNTIFS($E9:$E13,"DESKTOP",$F9:$F13,"*11*HOME*") -> 0
C25: Pro | D25: =COUNTIFS($E9:$E13,"LAPTOP",$F9:$F13,"*11*PRO*") -> 0 | E25: =COUNTIFS($E9:$E13,"DESKTOP",$F9:$F13,"*11*PRO*") -> 1
C26: Windows 10
C27: Pro OEM | D27: =COUNTIFS($E9:$E13,"LAPTOP",$F9:$F13,"*10*OEM*") -> 0 | E27: =COUNTIFS($E9:$E13,"DESKTOP",$F9:$F13,"*10*OEM*") -> 0
C28: Pro | D28: =COUNTIFS($E9:$E13,"LAPTOP",$F9:$F13,"*10*",$F9:$F13,"<>*OEM*") -> 0 | E28: =COUNTIFS($E9:$E13,"DESKTOP",$F9:$F13,"*10*",$F9:$F13,"<>*OEM*") -> 1
C29: Windows 7
C30: Pro GGWA | D30: =COUNTIFS($E9:$E13,"LAPTOP",$F9:$F13,"*7*",$F9:$F13,"*GGWA*") -> 1 | E30: =COUNTIFS($E9:$E13,"DESKTOP",$F9:$F13,"*7*",$F9:$F13,"*GGWA*") -> 2
C31: TOTAL | D31: =SUM(D23:D30) -> 1 | E31: =SUM(E23:E30) -> 4
D32: =D31+E31 -> 5

Sheet Kibawe BL
B2: RBT BANK, INC.
B3: SOFTWARE LICENSE INVENTORY
B4: ='Main Office'!B4:I4 -> As of September 2025
B6: KIBAWE BLU
B8: DESIGNATION | D8: USER | E8: ITEM TYPE | F8: OPERATING SYSTEM | G8: LICENSED | H8: OFFICE TOOLS | I8: CLIENT ACCESS | J8: SECTION
B9: 1 | C9: Acting BLU HEAD | D9: LAO, Lester Terex M. | E9: Laptop | F9: Win 11Pro OEM 64bit | G9: YES | H9: OPEN OFFICE/LIBREOFFICE | I9: Excluded | J9: Loans
B10: 2 | C10: Office Associate | D10: BANHAW, Jeniffer L. | E10: Desktop | F10: Win 11Pro OEM 64bit | G10: YES | H10: OPEN OFFICE/LIBREOFFICE | I10: Excluded | J10: Cash
B11: 3 | C11: Loans Bookkeeper / Accounting | D11: LACIA, Melvi Jane R. | E11: Desktop | F11: Win 11Pro OEM 64bit | G11: YES | H11: OPEN OFFICE/LIBREOFFICE | I11: Excluded | J11: Accounting
B12: 4 | C12: Loans Processor | D12: Loan Processor- Trainee | E12: Desktop | F12: Win 11Pro OEM 64bit | G12: YES | H12: OPEN OFFICE/LIBREOFFICE | I12: Excluded | J12: Loans
B13: 5 | C13: Account Officer | D13: Account Officer- Trainee | E13: Desktop | F13: Win 11Pro OEM 64bit | G13: YES | H13: OPEN OFFICE/LIBREOFFICE | I13: Excluded | J13: Loans
C16: SUMMARY | D16: OS | E16: MS OFFICE | F16: CAL | H16: MS OFFICE VERSION
C17: No. of Users w/ License | D17: =COUNTIF($G9:$G13,"YES") -> 5 | E17: =COUNTIFS($H9:$H13,"<>",$H9:$H13,"<>OPEN OFFICE/LIBREOFFICE") -> 0 | F17: =COUNTIFS($I9:$I13,"CAL") -> 0 | H17: MS Office 2010 | I17: =COUNTIF(H9:H13,"*2010") -> 0
C18: No. of Users w/o License | D18: =COUNTIF($G9:$G13,"NO") -> 0 | E18: =COUNTIFS($H9:$H13,"<>",$H9:$H13,"OPEN OFFICE/LIBREOFFICE") -> 5 | F18: =COUNTIFS($I9:$I13,"NONE") -> 0 | H18: MS Office 2016 | I18: =COUNTIF(H9:H13,"*2016") -> 0
E19: Excluded | F19: =COUNTIFS($I9:$I13,"EXCLUDED") -> 5 | H19: MS Office 2021 | I19: =COUNTIF(H9:H13,"*2021") -> 0
H20: MS Office 2024 | I20: =COUNTIF(H9:H13,"*2024") -> 0
C21: OS BREAKDOWN
D22: Laptop | E22: Desktop PC
C23: Windows 11
C24: Home | D24: =COUNTIFS($E9:$E13,"LAPTOP",$F9:$F13,"*11*HOME*") -> 0 | E24: =COUNTIFS($E9:$E13,"DESKTOP",$F9:$F13,"*11*HOME*") -> 0
C25: Pro | D25: =COUNTIFS($E9:$E13,"LAPTOP",$F9:$F13,"*11*PRO*") -> 1 | E25: =COUNTIFS($E9:$E13,"DESKTOP",$F9:$F13,"*11*PRO*") -> 4
C26: TOTAL | D26: =SUM(D23:D25) -> 1 | E26: =SUM(E23:E25) -> 4
D27: =D26+E26 -> 5

Sheet Spare
B2: RBT BANK, INC.
B3: SOFTWARE LICENSE INVENTORY
B4: As of January 2023
B6: SPARE LAPTOPS WITH LICENSES
B8: CURRENT LOCATION | D8: FORMER USER | E8: ITEM TYPE | F8: OPERATING SYSTEM | G8: LICENSED | H8: OFFICE TOOLS | I8: CLIENT ACCESS
B10: 1 | C10: MIS OFFICE | D10: VIRGENCITA DAISY Q. CARAEL | E10: Laptop | F10: Win 7 Pro GGWA | G10: YES | H10: OPEN OFFICE | I10: Excluded
B11: 2 | C11: MIS OFFICE | D11: PHSYCHE JOY B. CENA | E11: Laptop | F11: Win 8 OEM | G11: YES | H11: OPEN OFFICE | I11: Excluded
B12: 3 | C12: MIS OFFICE | D12: FREVIE EVE R. ALIDO | E12: Laptop | F12: Win 7 Pro GGWA | G12: YES | H12: OPEN OFFICE | I12: Excluded
B13: 4 | C13: MIS OFFICE | D13: IRA REGINE M. PANGAN | E13: Laptop | F13: Win 7 Pro GGWA | G13: YES | H13: OPEN OFFICE | I13: Excluded
C15: SUMMARY | D15: OS | E15: MS OFFICE | F15: CAL | H15: MS OFFICE VERSION
C16: No. of Users w/ License | D16: =COUNTIF($G10:$G13,"YES") -> 4 | E16: =COUNTIFS($H10:$H13,"<>",$H10:$H13,"<>OPEN OFFICE") -> 0 | F16: =COUNTIFS($I10:$I13,"CAL") -> 0 | H16: MS Office 2010 | I16: =COUNTIF(H10:H13,"*2010") -> 0
C17: No. of Users w/o License | D17: =COUNTIF($G10:$G13,"NO") -> 0 | E17: =COUNTIFS($H10:$H13,"<>",$H10:$H13,"OPEN OFFICE") -> 4 | F17: =COUNTIFS($I10:$I13,"NONE") -> 0 | H17: MS Office 2016 | I17: =COUNTIF(H10:H13,"*2016") -> 0
E18: Excluded | F18: =COUNTIFS($I10:$I13,"EXCLUDED") -> 4 | H18: MS Office 2021 | I18: =COUNTIF(H10:H13,"*2021") -> 0
H19: MS Office 2024 | I19: =COUNTIF(H10:H13,"*2024") -> 0
C20: OS BREAKDOWN
D21: Laptop | E21: Desktop PC
C22: Windows 10
C23: Home | D23: =COUNTIFS($E10:$E13,"LAPTOP",$F10:$F13,"*10*HOME*") -> 0 | E23: =COUNTIFS($E10:$E13,"DESKTOP",$F10:$F13,"*10*HOME*") -> 0
C24: Pro | D24: =COUNTIFS($E10:$E13,"LAPTOP",$F10:$F13,"*10*PRO*") -> 0 | E24: =COUNTIFS($E10:$E13,"DESKTOP",$F10:$F13,"*10*PRO*") -> 0
C25: Windows 10
C26: Pro OEM | D26: =COUNTIFS($E10:$E13,"LAPTOP",$F10:$F13,"*10*OEM*") -> 0 | E26: =COUNTIFS($E10:$E13,"DESKTOP",$F10:$F13,"*10*OEM*") -> 0
C27: Pro | D27: =COUNTIFS($E10:$E13,"LAPTOP",$F10:$F13,"*10*",$F10:$F13,"<>*OEM*") -> 0 | E27: =COUNTIFS($E10:$E13,"DESKTOP",$F10:$F13,"*10*",$F10:$F13,"<>*OEM*") -> 0
C28: Windows 8
C29: Pro OEM | D29: =COUNTIFS($E10:$E13,"LAPTOP",$F10:$F13,"*8*OEM*") -> 1 | E29: =COUNTIFS($E10:$E13,"DESKTOP",$F10:$F13,"*8*OEM*") -> 0
C30: Windows 7
C31: Pro GGWA | D31: =COUNTIFS($E10:$E13,"LAPTOP",$F10:$F13,"*7*GGWA*") -> 3 | E31: =COUNTIFS($E10:$E13,"DESKTOP",$F10:$F13,"*7*GGWA*") -> 0
C32: TOTAL | D32: =SUM(D22:D31) -> 4 | E32: =SUM(E22:E31) -> 0
D33: =D32+E32 -> 4

Sheet Summary (2)
A1: RBT BANK, INC.
A2: SOFTWARE LICENSE INVENTORY
A3: As of January 2023
A5: HEAD OFFICE | M5: BANKWIDE SUMMARY
M6: Users w/ License | P6: Users w/out License
A7: SUMMARY | D7: OS | E7: MS OFFICE | F7: CAL | H7: OS BREAKDOWN | M7: OS
A8: No. of Users w/ License | D8: ='Head Office'!D35 -> 25 | E8: ='Head Office'!E35 -> 7 | F8: ='Head Office'!F35 -> 1 | I8: Laptop | J8: Desktop PC | M8: Windows 11 | N8: =SUM(I10:J11,I27:J28,I44:J45,I61:J62,I78:J79,I95:J96,I112:J113,I129:J130,I146:J147,I163:J164) -> 23
A9: No. of Users w/out License | D9: ='Head Office'!D36 -> 0 | E9: ='Head Office'!E36 -> 18 | F9: ='Head Office'!F36 -> 0 | H9: Windows 11 | M9: Windows 10 | N9: =SUM(I13:J14,I30:J31,I47:J48,I64:J65,I81:J82,I98:J99,I115:J116,I132:J133,I149:J150,I166:J167) -> 55
E10: Excluded | F10: ='Head Office'!F37 -> 24 | H10: Home | I10: ='Head Office'!D42 -> 0 | J10: ='Head Office'!E42 -> 0 | M10: Windows 8 | N10: =SUM(I15:J15,I32:J32,I49:J49,I66:J66,I83:J83,I100:J100,I117:J117,I134:J134,I151:J151,I168:J168) -> 0
H11: Pro | I11: ='Head Office'!D43 -> 6 | J11: ='Head Office'!E43 -> 2 | M11: Windows 7 | N11: =SUM(I17:J18,I34:J35,I51:J52,I68:J69,I85:J86,I102:J103,I119:J120,I136:J137,I153:J154,I170:J171) -> 31
B12: MS OFFICE VERSION | H12: Windows 10
B13: MS Office 2010 | D13: ='Head Office'!I35 -> 3 | H13: Pro OEM | I13: ='Head Office'!D45 -> 5 | J13: ='Head Office'!E45 -> 0
B14: MS Office 2016 | D14: ='Head Office'!I36 -> 0 | H14: Pro | I14: ='Head Office'!D46 -> 1 | J14: ='Head Office'!E46 -> 7 | M14: Total | N14: =SUM(N8:N13) -> 109
B15: MS Office 2021 | D15: ='Head Office'!I37 -> 1 | H15: Windows 8 | I15: ='Head Office'!D47 -> 0 | J15: ='Head Office'!E47 -> 0 | M15: MS Office
B16: MS Office 2024 | D16: ='Head Office'!I38 -> 2 | H16: Windows 7 | M16: MS Office 2010 | N16: ='Head Office'!I35+'Main Office'!I24+'Jasaan Branch'!I29+'Salay Branch'!I23+'CDO Branch'!I29+'Maramag Branch'!I21+'Gingoog BL'!I18+'Camiguin BL'!I16+'Butuan BL'!I17+'Kibawe BL'!I17+Spare!I16 -> 23
H17: Ultimate / Starter | I17: ='Head Office'!D49 -> 0 | J17: ='Head Office'!E49 -> 0 | M17: MS Office 2016 | N17: ='Head Office'!I36+'Main Office'!I25+'Jasaan Branch'!I30+'Salay Branch'!I24+'CDO Branch'!I30+'Maramag Branch'!I22+'Gingoog BL'!I19+'Camiguin BL'!I17+'Butuan BL'!I18+'Kibawe BL'!I18+Spare!I17 -> 9
H18: Pro GGWA | I18: ='Head Office'!D50 -> 0 | J18: ='Head Office'!E50 -> 3 | M18: MS Office 2021 | N18: ='Head Office'!I37+'Main Office'!I26+'Jasaan Branch'!I31+'Salay Branch'!I25+'CDO Branch'!I31+'Maramag Branch'!I23+'Gingoog BL'!I20+'Camiguin BL'!I18+'Butuan BL'!I19+'Kibawe BL'!I19+Spare!I18 -> 1
H19: TOTAL | I19: =SUM(I9:I18) -> 12 | J19: =SUM(J9:J18) -> 12 | M19: MS Office 2024 | N19: ='Head Office'!I38+'Main Office'!I27+'Jasaan Branch'!I32+'Salay Branch'!I26+'CDO Branch'!I32+'Maramag Branch'!I24+'Gingoog BL'!I21+'Camiguin BL'!I19+'Butuan BL'!I20+'Kibawe BL'!I20+Spare!I19 -> 4
I20: =I19+J19 -> 24 | M20: Total | N20: =SUM(N16:N19) -> 37
A22: MAIN OFFICE
A24: SUMMARY | D24: OS | E24: MS OFFICE | F24: CAL | H24: OS BREAKDOWN
A25: No. of Users w/ License | D25: ='Main Office'!D24 -> 12 | E25: ='Main Office'!E24 -> 7 | F25: ='Main Office'!F24 -> 8 | I25: Laptop | J25: Desktop PC
A26: No. of Users w/out License | D26: ='Main Office'!D25 -> 0 | E26: ='Main Office'!E25 -> 5 | F26: ='Main Office'!F25 -> 4 | H26: Windows 11
E27: Excluded | F27: ='Main Office'!F26 -> 0 | H27: Home | I27: ='Main Office'!D32 -> 0 | J27: ='Main Office'!E32 -> 0
H28: Pro | I28: ='Main Office'!D33 -> 0 | J28: ='Main Office'!E33 -> 0
B29: MS OFFICE VERSION | H29: Windows 10
B30: MS Office 2010 | D30: ='Main Office'!I24 -> 5 | H30: Pro OEM | I30: ='Main Office'!D35 -> 0 | J30: ='Main Office'!E35 -> 0
B31: MS Office 2016 | D31: ='Main Office'!I25 -> 1 | H31: Pro | I31: ='Main Office'!D36 -> 0 | J31: ='Main Office'!E36 -> 11
B32: MS Office 2021 | D32: ='Main Office'!I26 -> 0 | H32: Windows 8
B33: MS Office 2024 | D33: ='Main Office'!I27 -> 0 | H33: Windows 7
H34: Ultimate / Starter | I34: ='Main Office'!D39 -> 0 | J34: ='Main Office'!E39 -> 0
H35: Pro GGWA | I35: ='Main Office'!D40 -> 0 | J35: ='Main Office'!E40 -> 0
H36: TOTAL | I36: =SUM(I26:I35) -> 0 | J36: =SUM(J26:J35) -> 11
I37: =I36+J36 -> 11
A39: JASAAN OFFICE
A41: SUMMARY | D41: OS | E41: MS OFFICE | F41: CAL | H41: OS BREAKDOWN
A42: No. of Users w/ License | D42: ='Jasaan Branch'!D29 -> 17 | E42: ='Jasaan Branch'!E29 -> 7 | F42: ='Jasaan Branch'!F29 -> 11 | I42: Laptop | J42: Desktop PC
A43: No. of Users w/out License | D43: ='Jasaan Branch'!D30 -> 0 | E43: ='Jasaan Branch'!E30 -> 10 | F43: ='Jasaan Branch'!F30 -> 4 | H43: Windows 11
E44: Excluded | F44: ='Jasaan Branch'!F31 -> 2 | H44: Home | I44: ='Jasaan Branch'!D36 -> 0 | J44: ='Jasaan Branch'!E36 -> 0
H45: Pro | I45: ='Jasaan Branch'!D37 -> 1 | J45: ='Jasaan Branch'!E37 -> 0
...

Sheet Summary
A1: RBT BANK, INC.
A2: SOFTWARE LICENSE INVENTORY
A3: As of January 2023
A7: HEAD OFFICE | L7: BANKWIDE SUMMARY
A9: SUMMARY | D9: OS | E9: MS OFFICE | F9: CAL | H9: OS BREAKDOWN | L9: Users w/ License | O9: Users w/out License
A10: No. of Users w/ License | D10: ='Head Office'!D35 -> 25 | E10: ='Head Office'!E35 -> 7 | F10: ='Head Office'!F35 -> 1 | I10: Laptop | J10: Desktop PC | L10: OS
A11: No. of Users w/out License | D11: ='Head Office'!D36 -> 0 | E11: ='Head Office'!E36 -> 18 | F11: ='Head Office'!F36 -> 0 | H11: Windows 11 | L11: Windows 7 | M11: 66 | O11: 0
E12: Excluded | F12: ='Head Office'!F37 -> 24 | H12: Home | L12: Windows 10 | M12: 22 | O12: 0
H13: Pro
H14: Windows 10
H15: Pro OEM | I15: 7 | J15: 0 | L15: Total | M15: =M11+M12 -> 88 | O15: s
H16: Pro | I16: 0 | J16: 9 | L16: MS Office
H17: Windows 8 | I17: 0 | J17: 0 | L17: MS Office 2010 | M17: 25 | O17: 0
H18: Windows 7 | L18: MS Office 2016 | M18: 5
H19: Pro GGWA | I19: 4 | J19: 3 | L19: Total | M19: =M17+M18 -> 30 | O19: 0
H20: Starter OEM | I20: 1 | J20: 0 | L20: CAL | M20: =SUM(F10,F26,F37,F48,F59,F71,F84,F95) -> 42 | O20: =SUM(F11,F27,F38,F49,F60,F72,F85,F96) -> 20
H21: TOTAL | I21: =SUM(I12:I20) -> 12 | J21: =SUM(J12:J20) -> 12
I22: =I21+J21 -> 24
A24: MAIN OFFICE | L24: LICENSE CONFIRMATION
A25: SUMMARY | D25: OS | E25: MS OFFICE | F25: CAL | H25: OS BREAKDOWN | L25: WINDOWS CLIENT
A26: No. of Users w/ License | D26: 14 | E26: =+'Main Office'!E24 -> 7 | F26: =+'Main Office'!F24 -> 8 | I26: Laptop | J26: Desktop PC | L26: Particular | M26: Date Licensed | O26: Quantity
A27: No. of Users w/out License | D27: 0 | E27: 8 | F27: =+'Main Office'!F25 -> 4 | H27: Windows 10 | L27: Windows 7 | M27: 40687 | O27: 60
E28: Excluded | F28: 1 | H28: Pro OEM | I28: 1 | J28: 0 | L28: Windows 10 | M28: 42816 | O28: 24
H29: Pro | I29: 0 | J29: 10 | L29: Windows 10 | M29: 43475 | O29: 4
H30: Windows 7 | L30: TOTAL | O30: 88
H31: Pro GGWA | I31: 0 | J31: 3 | L31: WINDOWS SERVER
H32: TOTAL | I32: =SUM(I27:I31) -> 1 | J32: =SUM(J27:J31) -> 13 | L32: Windows Server CAL | M32: 40687 | O32: 40
I33: =I32+J32 -> 14 | L33: Windows Server 2008 | M33: 40687 | O33: 4
L34: Windows Server 2016 | M34: 42816 | O34: 8
A35: SALAY BRANCH | L35: TOTAL | O35: 52
A36: SUMMARY | D36: OS | E36: MS OFFICE | F36: CAL | H36: OS BREAKDOWN | L36: MICROSOFT OFFICE
A37: No. of Users w/ License | D37: =+'Salay Branch'!D23 -> 11 | E37: =+'Salay Branch'!E23 -> 5 | F37: =+'Salay Branch'!F23 -> 8 | I37: Laptop | J37: Desktop PC | L37: Microsoft Office 2010 | M37: 40687 | O37: 25
A38: No. of Users w/out License | D38: =+'Salay Branch'!D24 -> 0 | E38: =+'Salay Branch'!E24 -> 6 | F38: =+'Salay Branch'!F24 -> 3 | H38: Windows 10 | L38: Microsoft Office 2016 | M38: 43670 | O38: 5
E39: Excluded | F39: 2 | H39: Pro OEM | I39: 1 | J39: 0 | L39: TOTAL | O39: 30
H40: Pro | I40: 0 | J40: 3
H41: Windows 7
H42: Pro GGWA | I42: 0 | J42: 7
H43: TOTAL | I43: =SUM(I38:I42) -> 1 | J43: =SUM(J38:J42) -> 10
I44: =I43+J43 -> 11
A46: JASAAN BRANCH | L46: LAPTOPS WITH FREE OEM LIMITED OS UPON LICENSE
...

Sheet License Confirmation Summary
B2: RBT BANK, INC.
B3: SOFTWARE LICENSE INVENTORY
B4: As of January 2023
B6: Product Description | D6: Microsoft Part Number | E6: Version | F6: Quantity | G6: Authorization Number | H6: License Number | I6: Distributor Purchase Order Number | J6: Licensed Date | K6: Type
B7: 1 | C7: Microsoft®WindowsProfessional 10 Sngl OLP 1License NoLevel Legalization GetGenuine | D7: FQC-09478 | E7: 10 | F7: 4 | G7: 98279325ZZS1903 | H7: 87482054 | I7: FP099011 | J7: 43475 | K7: Desktop OS
B8: 2 | C8: Microsoft®WindowsServerSTDCORE 2016 Sngl OLP 2Licenses NoLevel CoreLic | D8: 9EM-00124 | E8: 2016 | F8: 8 | G8: 98276546ZZS1903 | H8: 68213266 | I8: 100103668 | J8: 42816 | K8: Server OS
B9: 3 | C9: Microsoft®WindowsProfessional 10 Sngl OLP 1License NoLevel Legalization GetGenuine | D9: FQC-09478 | E9: 10 | F9: 24 | G9: 98279325ZZS1903 | H9: 68213269 | I9: 100103667 | J9: 42816 | K9: Desktop OS
B10: 4 | C10: Microsoft®WindowsProfessional 7 Sngl OLP 1License NoLevel Legalization GetGenuine | D10: FQC-02872 | E10: 7 | F10: 60 | G10: 68516923ZZS1305 | H10: 48539746 | I10: 004800 | J10: 40687 | K10: Desktop OS
B11: 5 | C11: Microsoft® Office 2010 Sngl OPEN 1 License No Level | D11: 021-09707 | E11: 2010 | F11: 25 | G11: 68516159ZZS1305 | H11: 48539745 | I11: 004801 | J11: 40687 | K11: MS Office
B12: 6 | C12: Microsoft® Windows® Server CAL 2008 Sngl OPEN 1 License No Level Device CAL Device CAL | D12: R18-02729 | E12: 2008 | F12: 40 | G12: 68516159ZZS1305 | H12: 48539745 | I12: 004801 | J12: 40687 | K12: Server Client Access
B13: 7 | C13: Microsoft® Windows® Server Standard 2008 R2 Sngl OPEN 1 License No Level | D13: P73-04982 | E13: 2008 R2 | F13: 4 | G13: 68516159ZZS1305 | H13: 48539745 | I13: 004801 | J13: 40687 | K13: Server OS

Sheet Total
A1: CASH MAIN
A3: WIN 7
A4: WIN 10
